[2025-03-30T17:13:32.562+0000] {local_task_job_runner.py:120} INFO - ::group::Pre task execution logs
[2025-03-30T17:13:32.579+0000] {taskinstance.py:2076} INFO - Dependencies all met for dep_context=non-requeueable deps ti=<TaskInstance: dag_deliverable.create_hive_table manual__2025-03-30T17:13:24.172060+00:00 [queued]>
[2025-03-30T17:13:32.583+0000] {taskinstance.py:2076} INFO - Dependencies all met for dep_context=requeueable deps ti=<TaskInstance: dag_deliverable.create_hive_table manual__2025-03-30T17:13:24.172060+00:00 [queued]>
[2025-03-30T17:13:32.583+0000] {taskinstance.py:2306} INFO - Starting attempt 1 of 2
[2025-03-30T17:13:32.596+0000] {taskinstance.py:2330} INFO - Executing <Task(PythonOperator): create_hive_table> on 2025-03-30 17:13:24.172060+00:00
[2025-03-30T17:13:32.601+0000] {standard_task_runner.py:64} INFO - Started process 222 to run task
[2025-03-30T17:13:32.603+0000] {standard_task_runner.py:90} INFO - Running: ['airflow', 'tasks', 'run', 'dag_deliverable', 'create_hive_table', 'manual__2025-03-30T17:13:24.172060+00:00', '--job-id', '111', '--raw', '--subdir', 'DAGS_FOLDER/dag_deliverable.py', '--cfg-path', '/tmp/tmpage8w8lf']
[2025-03-30T17:13:32.604+0000] {standard_task_runner.py:91} INFO - Job 111: Subtask create_hive_table
[2025-03-30T17:13:32.634+0000] {task_command.py:426} INFO - Running <TaskInstance: dag_deliverable.create_hive_table manual__2025-03-30T17:13:24.172060+00:00 [running]> on host airflow
[2025-03-30T17:13:32.690+0000] {taskinstance.py:2648} INFO - Exporting env vars: AIRFLOW_CTX_DAG_OWNER='airflow' AIRFLOW_CTX_DAG_ID='dag_deliverable' AIRFLOW_CTX_TASK_ID='create_hive_table' AIRFLOW_CTX_EXECUTION_DATE='2025-03-30T17:13:24.172060+00:00' AIRFLOW_CTX_TRY_NUMBER='1' AIRFLOW_CTX_DAG_RUN_ID='manual__2025-03-30T17:13:24.172060+00:00'
[2025-03-30T17:13:32.690+0000] {taskinstance.py:430} INFO - ::endgroup::
[2025-03-30T17:13:32.704+0000] {base.py:84} INFO - Using connection ID 'hive_default' for task execution.
[2025-03-30T17:13:32.735+0000] {hive.py:475} INFO - USE `default`
[2025-03-30T17:13:32.760+0000] {hive.py:475} INFO - 
            CREATE TABLE IF NOT EXISTS tienda.usuarios (
                id INT,
                nombre STRING,
                email STRING
            )
            ROW FORMAT DELIMITED
            FIELDS TERMINATED BY ','
            STORED AS TEXTFILE
        
[2025-03-30T17:13:32.900+0000] {dag_deliverable.py:98} ERROR - ‚ùå Error al crear la tabla en Hive: TExecuteStatementResp(status=TStatus(statusCode=3, infoMessages=['Server-side error; please check HS2 logs.'], sqlState='42000', errorCode=10072, errorMessage='Error while compiling statement: FAILED: SemanticException [Error 10072]: Database does not exist: tienda'), operationHandle=None)
[2025-03-30T17:13:32.900+0000] {taskinstance.py:441} INFO - ::group::Post task execution logs
[2025-03-30T17:13:32.900+0000] {taskinstance.py:2905} ERROR - Task failed with exception
Traceback (most recent call last):
  File "/home/airflow/.local/lib/python3.9/site-packages/airflow/models/taskinstance.py", line 465, in _execute_task
    result = _execute_callable(context=context, **execute_callable_kwargs)
  File "/home/airflow/.local/lib/python3.9/site-packages/airflow/models/taskinstance.py", line 432, in _execute_callable
    return execute_callable(context=context, **execute_callable_kwargs)
  File "/home/airflow/.local/lib/python3.9/site-packages/airflow/models/baseoperator.py", line 401, in wrapper
    return func(self, *args, **kwargs)
  File "/home/airflow/.local/lib/python3.9/site-packages/airflow/operators/python.py", line 235, in execute
    return_value = self.execute_callable()
  File "/home/airflow/.local/lib/python3.9/site-packages/airflow/operators/python.py", line 252, in execute_callable
    return self.python_callable(*self.op_args, **self.op_kwargs)
  File "/opt/airflow/dags/dag_deliverable.py", line 84, in create_table
    cursor.execute("""
  File "/home/airflow/.local/lib/python3.9/site-packages/pyhive/hive.py", line 481, in execute
    _check_status(response)
  File "/home/airflow/.local/lib/python3.9/site-packages/pyhive/hive.py", line 611, in _check_status
    raise OperationalError(response)
pyhive.exc.OperationalError: TExecuteStatementResp(status=TStatus(statusCode=3, infoMessages=['Server-side error; please check HS2 logs.'], sqlState='42000', errorCode=10072, errorMessage='Error while compiling statement: FAILED: SemanticException [Error 10072]: Database does not exist: tienda'), operationHandle=None)
[2025-03-30T17:13:32.905+0000] {taskinstance.py:1206} INFO - Marking task as UP_FOR_RETRY. dag_id=dag_deliverable, task_id=create_hive_table, run_id=manual__2025-03-30T17:13:24.172060+00:00, execution_date=20250330T171324, start_date=20250330T171332, end_date=20250330T171332
[2025-03-30T17:13:32.917+0000] {standard_task_runner.py:110} ERROR - Failed to execute job 111 for task create_hive_table (TExecuteStatementResp(status=TStatus(statusCode=3, infoMessages=['Server-side error; please check HS2 logs.'], sqlState='42000', errorCode=10072, errorMessage='Error while compiling statement: FAILED: SemanticException [Error 10072]: Database does not exist: tienda'), operationHandle=None); 222)
[2025-03-30T17:13:32.935+0000] {local_task_job_runner.py:243} INFO - Task exited with return code 1
[2025-03-30T17:13:32.945+0000] {taskinstance.py:3503} INFO - 0 downstream tasks scheduled from follow-on schedule check
[2025-03-30T17:13:32.945+0000] {local_task_job_runner.py:222} INFO - ::endgroup::
