[2025-03-30T18:12:44.964+0000] {local_task_job_runner.py:120} INFO - ::group::Pre task execution logs
[2025-03-30T18:12:44.980+0000] {taskinstance.py:2076} INFO - Dependencies all met for dep_context=non-requeueable deps ti=<TaskInstance: dag_deliverable.query_hive_data manual__2025-03-30T18:12:42.662021+00:00 [queued]>
[2025-03-30T18:12:44.984+0000] {taskinstance.py:2076} INFO - Dependencies all met for dep_context=requeueable deps ti=<TaskInstance: dag_deliverable.query_hive_data manual__2025-03-30T18:12:42.662021+00:00 [queued]>
[2025-03-30T18:12:44.984+0000] {taskinstance.py:2306} INFO - Starting attempt 1 of 2
[2025-03-30T18:12:44.997+0000] {taskinstance.py:2330} INFO - Executing <Task(PythonOperator): query_hive_data> on 2025-03-30 18:12:42.662021+00:00
[2025-03-30T18:12:45.003+0000] {standard_task_runner.py:64} INFO - Started process 187 to run task
[2025-03-30T18:12:45.005+0000] {standard_task_runner.py:90} INFO - Running: ['airflow', 'tasks', 'run', 'dag_deliverable', 'query_hive_data', 'manual__2025-03-30T18:12:42.662021+00:00', '--job-id', '171', '--raw', '--subdir', 'DAGS_FOLDER/dag_deliverable.py', '--cfg-path', '/tmp/tmp9qv_4e2u']
[2025-03-30T18:12:45.006+0000] {standard_task_runner.py:91} INFO - Job 171: Subtask query_hive_data
[2025-03-30T18:12:45.031+0000] {task_command.py:426} INFO - Running <TaskInstance: dag_deliverable.query_hive_data manual__2025-03-30T18:12:42.662021+00:00 [running]> on host airflow
[2025-03-30T18:12:45.084+0000] {taskinstance.py:2648} INFO - Exporting env vars: AIRFLOW_CTX_DAG_OWNER='airflow' AIRFLOW_CTX_DAG_ID='dag_deliverable' AIRFLOW_CTX_TASK_ID='query_hive_data' AIRFLOW_CTX_EXECUTION_DATE='2025-03-30T18:12:42.662021+00:00' AIRFLOW_CTX_TRY_NUMBER='1' AIRFLOW_CTX_DAG_RUN_ID='manual__2025-03-30T18:12:42.662021+00:00'
[2025-03-30T18:12:45.084+0000] {taskinstance.py:430} INFO - ::endgroup::
[2025-03-30T18:12:45.100+0000] {base.py:84} INFO - Using connection ID 'hive_default' for task execution.
[2025-03-30T18:12:45.127+0000] {hive.py:475} INFO - USE `default`
[2025-03-30T18:12:45.149+0000] {hive.py:475} INFO - SELECT * FROM weather.sensor_data 
[2025-03-30T18:12:45.436+0000] {dag_deliverable.py:182} ERROR - ‚ùå Error al consultar Hive: TExecuteStatementResp(status=TStatus(statusCode=3, infoMessages=['Server-side error; please check HS2 logs.'], sqlState=None, errorCode=1, errorMessage='Error while compiling statement: java.io.IOException: java.io.IOException: Not a file: hdfs://namenode:9000/topics/sensores/partition=0'), operationHandle=None)
[2025-03-30T18:12:45.436+0000] {taskinstance.py:441} INFO - ::group::Post task execution logs
[2025-03-30T18:12:45.437+0000] {taskinstance.py:2905} ERROR - Task failed with exception
Traceback (most recent call last):
  File "/home/airflow/.local/lib/python3.9/site-packages/airflow/models/taskinstance.py", line 465, in _execute_task
    result = _execute_callable(context=context, **execute_callable_kwargs)
  File "/home/airflow/.local/lib/python3.9/site-packages/airflow/models/taskinstance.py", line 432, in _execute_callable
    return execute_callable(context=context, **execute_callable_kwargs)
  File "/home/airflow/.local/lib/python3.9/site-packages/airflow/models/baseoperator.py", line 401, in wrapper
    return func(self, *args, **kwargs)
  File "/home/airflow/.local/lib/python3.9/site-packages/airflow/operators/python.py", line 235, in execute
    return_value = self.execute_callable()
  File "/home/airflow/.local/lib/python3.9/site-packages/airflow/operators/python.py", line 252, in execute_callable
    return self.python_callable(*self.op_args, **self.op_kwargs)
  File "/opt/airflow/dags/dag_deliverable.py", line 163, in query_hive
    cursor.execute(f"""SELECT * FROM {HIVE_TABLE} """)
  File "/home/airflow/.local/lib/python3.9/site-packages/pyhive/hive.py", line 481, in execute
    _check_status(response)
  File "/home/airflow/.local/lib/python3.9/site-packages/pyhive/hive.py", line 611, in _check_status
    raise OperationalError(response)
pyhive.exc.OperationalError: TExecuteStatementResp(status=TStatus(statusCode=3, infoMessages=['Server-side error; please check HS2 logs.'], sqlState=None, errorCode=1, errorMessage='Error while compiling statement: java.io.IOException: java.io.IOException: Not a file: hdfs://namenode:9000/topics/sensores/partition=0'), operationHandle=None)
[2025-03-30T18:12:45.444+0000] {taskinstance.py:1206} INFO - Marking task as UP_FOR_RETRY. dag_id=dag_deliverable, task_id=query_hive_data, run_id=manual__2025-03-30T18:12:42.662021+00:00, execution_date=20250330T181242, start_date=20250330T181244, end_date=20250330T181245
[2025-03-30T18:12:45.465+0000] {standard_task_runner.py:110} ERROR - Failed to execute job 171 for task query_hive_data (TExecuteStatementResp(status=TStatus(statusCode=3, infoMessages=['Server-side error; please check HS2 logs.'], sqlState=None, errorCode=1, errorMessage='Error while compiling statement: java.io.IOException: java.io.IOException: Not a file: hdfs://namenode:9000/topics/sensores/partition=0'), operationHandle=None); 187)
[2025-03-30T18:12:45.498+0000] {local_task_job_runner.py:243} INFO - Task exited with return code 1
[2025-03-30T18:12:45.508+0000] {taskinstance.py:3503} INFO - 0 downstream tasks scheduled from follow-on schedule check
[2025-03-30T18:12:45.509+0000] {local_task_job_runner.py:222} INFO - ::endgroup::
